[2024-01-19T00:09:21.054+0000] {taskinstance.py:1159} INFO - Dependencies all met for dep_context=non-requeueable deps ti=<TaskInstance: fetch_and_save_historical_data.fetch_and_save_hitstorical_data manual__2024-01-19T00:09:14.756571+00:00 [queued]>
[2024-01-19T00:09:21.061+0000] {taskinstance.py:1159} INFO - Dependencies all met for dep_context=requeueable deps ti=<TaskInstance: fetch_and_save_historical_data.fetch_and_save_hitstorical_data manual__2024-01-19T00:09:14.756571+00:00 [queued]>
[2024-01-19T00:09:21.061+0000] {taskinstance.py:1361} INFO - Starting attempt 1 of 1
[2024-01-19T00:09:21.075+0000] {taskinstance.py:1382} INFO - Executing <Task(PythonOperator): fetch_and_save_hitstorical_data> on 2024-01-19 00:09:14.756571+00:00
[2024-01-19T00:09:21.078+0000] {standard_task_runner.py:57} INFO - Started process 6808 to run task
[2024-01-19T00:09:21.081+0000] {standard_task_runner.py:84} INFO - Running: ['***', 'tasks', 'run', 'fetch_and_save_historical_data', 'fetch_and_save_hitstorical_data', 'manual__2024-01-19T00:09:14.756571+00:00', '--job-id', '48', '--raw', '--subdir', 'DAGS_FOLDER/fetch_close_price.py', '--cfg-path', '/tmp/tmp04nmgs5l']
[2024-01-19T00:09:21.083+0000] {standard_task_runner.py:85} INFO - Job 48: Subtask fetch_and_save_hitstorical_data
[2024-01-19T00:09:21.149+0000] {task_command.py:415} INFO - Running <TaskInstance: fetch_and_save_historical_data.fetch_and_save_hitstorical_data manual__2024-01-19T00:09:14.756571+00:00 [running]> on host 36e53310e6a3
[2024-01-19T00:09:21.291+0000] {taskinstance.py:1660} INFO - Exporting env vars: AIRFLOW_CTX_DAG_OWNER='fatine' AIRFLOW_CTX_DAG_ID='fetch_and_save_historical_data' AIRFLOW_CTX_TASK_ID='fetch_and_save_hitstorical_data' AIRFLOW_CTX_EXECUTION_DATE='2024-01-19T00:09:14.756571+00:00' AIRFLOW_CTX_TRY_NUMBER='1' AIRFLOW_CTX_DAG_RUN_ID='manual__2024-01-19T00:09:14.756571+00:00'
[2024-01-19T00:09:21.866+0000] {fetch_close_price.py:74} WARNING - Cluster.__init__ called with contact_points specified, but no load_balancing_policy. In the next major version, this will raise an error; please specify a load-balancing policy. (contact_points = ['localhost'], lbp = None)
[2024-01-19T00:09:21.868+0000] {fetch_close_price.py:75} WARNING - [control connection] Error connecting to ::1:9042:
Traceback (most recent call last):
  File "cassandra/cluster.py", line 3577, in cassandra.cluster.ControlConnection._reconnect_internal
  File "cassandra/cluster.py", line 3599, in cassandra.cluster.ControlConnection._try_connect
  File "cassandra/cluster.py", line 1670, in cassandra.cluster.Cluster.connection_factory
  File "cassandra/connection.py", line 846, in cassandra.connection.Connection.factory
  File "/home/airflow/.local/lib/python3.9/site-packages/cassandra/io/asyncorereactor.py", line 354, in __init__
    self._connect_socket()
  File "cassandra/connection.py", line 951, in cassandra.connection.Connection._connect_socket
OSError: [Errno 99] Tried connecting to [('::1', 9042, 0, 0)]. Last error: Cannot assign requested address
[2024-01-19T00:09:21.870+0000] {fetch_close_price.py:75} WARNING - [control connection] Error connecting to 127.0.0.1:9042:
Traceback (most recent call last):
  File "cassandra/cluster.py", line 3577, in cassandra.cluster.ControlConnection._reconnect_internal
  File "cassandra/cluster.py", line 3599, in cassandra.cluster.ControlConnection._try_connect
  File "cassandra/cluster.py", line 1670, in cassandra.cluster.Cluster.connection_factory
  File "cassandra/connection.py", line 846, in cassandra.connection.Connection.factory
  File "/home/airflow/.local/lib/python3.9/site-packages/cassandra/io/asyncorereactor.py", line 354, in __init__
    self._connect_socket()
  File "cassandra/connection.py", line 951, in cassandra.connection.Connection._connect_socket
ConnectionRefusedError: [Errno 111] Tried connecting to [('127.0.0.1', 9042)]. Last error: Connection refused
[2024-01-19T00:09:21.871+0000] {fetch_close_price.py:75} ERROR - Control connection failed to connect, shutting down Cluster:
Traceback (most recent call last):
  File "cassandra/cluster.py", line 1740, in cassandra.cluster.Cluster.connect
  File "cassandra/cluster.py", line 3543, in cassandra.cluster.ControlConnection.connect
  File "cassandra/cluster.py", line 3588, in cassandra.cluster.ControlConnection._reconnect_internal
cassandra.cluster.NoHostAvailable: ('Unable to connect to any servers', {'::1:9042': OSError(99, "Tried connecting to [('::1', 9042, 0, 0)]. Last error: Cannot assign requested address"), '127.0.0.1:9042': ConnectionRefusedError(111, "Tried connecting to [('127.0.0.1', 9042)]. Last error: Connection refused")})
[2024-01-19T00:09:21.872+0000] {taskinstance.py:1943} ERROR - Task failed with exception
Traceback (most recent call last):
  File "/home/airflow/.local/lib/python3.9/site-packages/airflow/operators/python.py", line 192, in execute
    return_value = self.execute_callable()
  File "/home/airflow/.local/lib/python3.9/site-packages/airflow/operators/python.py", line 209, in execute_callable
    return self.python_callable(*self.op_args, **self.op_kwargs)
  File "/opt/airflow/dags/fetch_close_price.py", line 75, in fetch_and_save_data
    session = cluster.connect()
  File "cassandra/cluster.py", line 1717, in cassandra.cluster.Cluster.connect
  File "cassandra/cluster.py", line 1753, in cassandra.cluster.Cluster.connect
  File "cassandra/cluster.py", line 1740, in cassandra.cluster.Cluster.connect
  File "cassandra/cluster.py", line 3543, in cassandra.cluster.ControlConnection.connect
  File "cassandra/cluster.py", line 3588, in cassandra.cluster.ControlConnection._reconnect_internal
cassandra.cluster.NoHostAvailable: ('Unable to connect to any servers', {'::1:9042': OSError(99, "Tried connecting to [('::1', 9042, 0, 0)]. Last error: Cannot assign requested address"), '127.0.0.1:9042': ConnectionRefusedError(111, "Tried connecting to [('127.0.0.1', 9042)]. Last error: Connection refused")})
[2024-01-19T00:09:21.882+0000] {taskinstance.py:1400} INFO - Marking task as FAILED. dag_id=fetch_and_save_historical_data, task_id=fetch_and_save_hitstorical_data, execution_date=20240119T000914, start_date=20240119T000921, end_date=20240119T000921
[2024-01-19T00:09:21.898+0000] {standard_task_runner.py:104} ERROR - Failed to execute job 48 for task fetch_and_save_hitstorical_data (('Unable to connect to any servers', {'::1:9042': OSError(99, "Tried connecting to [('::1', 9042, 0, 0)]. Last error: Cannot assign requested address"), '127.0.0.1:9042': ConnectionRefusedError(111, "Tried connecting to [('127.0.0.1', 9042)]. Last error: Connection refused")}); 6808)
[2024-01-19T00:09:21.939+0000] {local_task_job_runner.py:228} INFO - Task exited with return code 1
[2024-01-19T00:09:21.959+0000] {taskinstance.py:2784} INFO - 0 downstream tasks scheduled from follow-on schedule check
